[2025-08-02 17:15:17,344: INFO: model_train: >>>>>> stage Model Training Stage started <<<<<<]
[2025-08-02 17:23:03,367: INFO: model_train: >>>>>> stage Model Training Stage started <<<<<<]
[2025-08-02 17:28:09,750: INFO: model_train: >>>>>> stage Model Training Stage started <<<<<<]
[2025-08-02 17:34:00,787: ERROR: model_train: INTERNAL_ERROR: Response: {'error': 'unsupported endpoint, please contact support@dagshub.com'}]
Traceback (most recent call last):
  File "C:\Users\sures\Downloads\Turbine_RUL_MLPipeline\model_train.py", line 24, in <module>
    model_path, metrics = obj.main()
  File "C:\Users\sures\Downloads\Turbine_RUL_MLPipeline\model_train.py", line 16, in main
    model_path, metrics = model_trainer.initiate_model_training()
  File "C:\Users\sures\Downloads\Turbine_RUL_MLPipeline\src\Turbine_RUL\components\model_training.py", line 258, in initiate_model_training
    mlflow.sklearn.log_model(model, "model")
  File "C:\Users\sures\anaconda3\envs\venv\lib\site-packages\mlflow\sklearn\__init__.py", line 426, in log_model
    return Model.log(
  File "C:\Users\sures\anaconda3\envs\venv\lib\site-packages\mlflow\models\model.py", line 1161, in log
    model = mlflow.initialize_logged_model(
  File "C:\Users\sures\anaconda3\envs\venv\lib\site-packages\mlflow\tracking\fluent.py", line 2130, in initialize_logged_model
    model = _create_logged_model(
  File "C:\Users\sures\anaconda3\envs\venv\lib\site-packages\mlflow\tracking\fluent.py", line 2257, in _create_logged_model
    return MlflowClient().create_logged_model(
  File "C:\Users\sures\anaconda3\envs\venv\lib\site-packages\mlflow\tracking\client.py", line 5369, in create_logged_model
    return self._tracking_client.create_logged_model(
  File "C:\Users\sures\anaconda3\envs\venv\lib\site-packages\mlflow\tracking\_tracking_service\client.py", line 824, in create_logged_model
    return self.store.create_logged_model(
  File "C:\Users\sures\anaconda3\envs\venv\lib\site-packages\mlflow\store\tracking\rest_store.py", line 936, in create_logged_model
    response_proto = self._call_endpoint(CreateLoggedModel, req_body)
  File "C:\Users\sures\anaconda3\envs\venv\lib\site-packages\mlflow\store\tracking\rest_store.py", line 135, in _call_endpoint
    return call_endpoint(
  File "C:\Users\sures\anaconda3\envs\venv\lib\site-packages\mlflow\utils\rest_utils.py", line 594, in call_endpoint
    response = verify_rest_response(response, endpoint)
  File "C:\Users\sures\anaconda3\envs\venv\lib\site-packages\mlflow\utils\rest_utils.py", line 308, in verify_rest_response
    raise RestException(json.loads(response.text))
mlflow.exceptions.RestException: INTERNAL_ERROR: Response: {'error': 'unsupported endpoint, please contact support@dagshub.com'}
[2025-08-02 17:44:08,101: INFO: model_train: >>>>>> stage Model Training Stage started <<<<<<]
[2025-08-02 18:00:33,185: INFO: model_train: >>>>>> stage Model Training Stage completed <<<<<<

x==========x]
[2025-08-02 18:32:29,913: INFO: model_predict: >>>>>> stage Model Prediction Stage started <<<<<<]
[2025-08-02 18:32:30,006: ERROR: model_predict: file must have 'read' and 'readline' attributes]
Traceback (most recent call last):
  File "C:\Users\sures\Downloads\Turbine_RUL_MLPipeline\model_predict.py", line 24, in <module>
    predictions_path, evaluation_metrics_path = obj.main()
  File "C:\Users\sures\Downloads\Turbine_RUL_MLPipeline\model_predict.py", line 16, in main
    predictions_path, evaluation_metrics_path = model_predictor.initiate_model_prediction()
  File "C:\Users\sures\Downloads\Turbine_RUL_MLPipeline\src\Turbine_RUL\components\model_prediction.py", line 35, in initiate_model_prediction
    preprocessor = pickle.load(self.config.preprocessor_path)
TypeError: file must have 'read' and 'readline' attributes
[2025-08-02 18:33:22,636: INFO: model_predict: >>>>>> stage Model Prediction Stage started <<<<<<]
[2025-08-02 18:33:22,719: ERROR: model_predict: file must have 'read' and 'readline' attributes]
Traceback (most recent call last):
  File "C:\Users\sures\Downloads\Turbine_RUL_MLPipeline\model_predict.py", line 24, in <module>
    predictions_path, evaluation_metrics_path = obj.main()
  File "C:\Users\sures\Downloads\Turbine_RUL_MLPipeline\model_predict.py", line 16, in main
    predictions_path, evaluation_metrics_path = model_predictor.initiate_model_prediction()
  File "C:\Users\sures\Downloads\Turbine_RUL_MLPipeline\src\Turbine_RUL\components\model_prediction.py", line 35, in initiate_model_prediction
    preprocessor = pickle.load(self.config.preprocessor_path)
TypeError: file must have 'read' and 'readline' attributes
[2025-08-02 18:38:02,017: INFO: model_predict: >>>>>> stage Model Prediction Stage started <<<<<<]
[2025-08-02 18:46:14,123: ERROR: model_predict: index 22 is out of bounds for axis 1 with size 16]
Traceback (most recent call last):
  File "C:\Users\sures\Downloads\Turbine_RUL_MLPipeline\model_predict.py", line 24, in <module>
    predictions_path, evaluation_metrics_path = obj.main()
  File "C:\Users\sures\Downloads\Turbine_RUL_MLPipeline\model_predict.py", line 16, in main
    predictions_path, evaluation_metrics_path = model_predictor.initiate_model_prediction()
  File "C:\Users\sures\Downloads\Turbine_RUL_MLPipeline\src\Turbine_RUL\components\model_prediction.py", line 159, in initiate_model_prediction
    predictions = model.predict(X_test_last[working_features].values)
  File "C:\Users\sures\anaconda3\envs\venv\lib\site-packages\ngboost\ngboost.py", line 590, in predict
    return self.pred_dist(X, max_iter=max_iter).predict()
  File "C:\Users\sures\anaconda3\envs\venv\lib\site-packages\ngboost\ngboost.py", line 543, in pred_dist
    params = np.asarray(self.pred_param(X, max_iter))
  File "C:\Users\sures\anaconda3\envs\venv\lib\site-packages\ngboost\ngboost.py", line 136, in pred_param
    resids = np.array([model.predict(X[:, col_idx]) for model in models]).T
  File "C:\Users\sures\anaconda3\envs\venv\lib\site-packages\ngboost\ngboost.py", line 136, in <listcomp>
    resids = np.array([model.predict(X[:, col_idx]) for model in models]).T
IndexError: index 22 is out of bounds for axis 1 with size 16
[2025-08-02 18:52:04,683: INFO: model_predict: >>>>>> stage Model Prediction Stage started <<<<<<]
[2025-08-02 19:00:15,930: ERROR: model_predict: index 22 is out of bounds for axis 1 with size 16]
Traceback (most recent call last):
  File "C:\Users\sures\Downloads\Turbine_RUL_MLPipeline\model_predict.py", line 24, in <module>
    predictions_path, evaluation_metrics_path = obj.main()
  File "C:\Users\sures\Downloads\Turbine_RUL_MLPipeline\model_predict.py", line 16, in main
    predictions_path, evaluation_metrics_path = model_predictor.initiate_model_prediction()
  File "C:\Users\sures\Downloads\Turbine_RUL_MLPipeline\src\Turbine_RUL\components\model_prediction.py", line 153, in initiate_model_prediction
    predictions = model.predict(X_test_last[working_features].values)
  File "C:\Users\sures\anaconda3\envs\venv\lib\site-packages\ngboost\ngboost.py", line 590, in predict
    return self.pred_dist(X, max_iter=max_iter).predict()
  File "C:\Users\sures\anaconda3\envs\venv\lib\site-packages\ngboost\ngboost.py", line 543, in pred_dist
    params = np.asarray(self.pred_param(X, max_iter))
  File "C:\Users\sures\anaconda3\envs\venv\lib\site-packages\ngboost\ngboost.py", line 136, in pred_param
    resids = np.array([model.predict(X[:, col_idx]) for model in models]).T
  File "C:\Users\sures\anaconda3\envs\venv\lib\site-packages\ngboost\ngboost.py", line 136, in <listcomp>
    resids = np.array([model.predict(X[:, col_idx]) for model in models]).T
IndexError: index 22 is out of bounds for axis 1 with size 16
[2025-08-02 19:02:05,719: INFO: model_predict: >>>>>> stage Model Prediction Stage started <<<<<<]
[2025-08-02 19:29:06,087: ERROR: model_predict: index 22 is out of bounds for axis 1 with size 16]
Traceback (most recent call last):
  File "C:\Users\sures\Downloads\Turbine_RUL_MLPipeline\model_predict.py", line 24, in <module>
    predictions_path, evaluation_metrics_path = obj.main()
  File "C:\Users\sures\Downloads\Turbine_RUL_MLPipeline\model_predict.py", line 16, in main
    predictions_path, evaluation_metrics_path = model_predictor.initiate_model_prediction()
  File "C:\Users\sures\Downloads\Turbine_RUL_MLPipeline\src\Turbine_RUL\components\model_prediction.py", line 168, in initiate_model_prediction
    predictions = model.predict(X_test_last[working_features].values)
  File "C:\Users\sures\anaconda3\envs\venv\lib\site-packages\ngboost\ngboost.py", line 590, in predict
    return self.pred_dist(X, max_iter=max_iter).predict()
  File "C:\Users\sures\anaconda3\envs\venv\lib\site-packages\ngboost\ngboost.py", line 543, in pred_dist
    params = np.asarray(self.pred_param(X, max_iter))
  File "C:\Users\sures\anaconda3\envs\venv\lib\site-packages\ngboost\ngboost.py", line 136, in pred_param
    resids = np.array([model.predict(X[:, col_idx]) for model in models]).T
  File "C:\Users\sures\anaconda3\envs\venv\lib\site-packages\ngboost\ngboost.py", line 136, in <listcomp>
    resids = np.array([model.predict(X[:, col_idx]) for model in models]).T
IndexError: index 22 is out of bounds for axis 1 with size 16
[2025-08-02 19:30:26,223: INFO: model_predict: >>>>>> stage Model Prediction Stage started <<<<<<]
[2025-08-02 19:35:54,402: ERROR: model_predict: index 23 is out of bounds for axis 1 with size 23]
Traceback (most recent call last):
  File "C:\Users\sures\Downloads\Turbine_RUL_MLPipeline\model_predict.py", line 24, in <module>
    predictions_path, evaluation_metrics_path = obj.main()
  File "C:\Users\sures\Downloads\Turbine_RUL_MLPipeline\model_predict.py", line 16, in main
    predictions_path, evaluation_metrics_path = model_predictor.initiate_model_prediction()
  File "C:\Users\sures\Downloads\Turbine_RUL_MLPipeline\src\Turbine_RUL\components\model_prediction.py", line 171, in initiate_model_prediction
    predictions = model.predict(X_test_last[working_features].values)
  File "C:\Users\sures\anaconda3\envs\venv\lib\site-packages\ngboost\ngboost.py", line 590, in predict
    return self.pred_dist(X, max_iter=max_iter).predict()
  File "C:\Users\sures\anaconda3\envs\venv\lib\site-packages\ngboost\ngboost.py", line 543, in pred_dist
    params = np.asarray(self.pred_param(X, max_iter))
  File "C:\Users\sures\anaconda3\envs\venv\lib\site-packages\ngboost\ngboost.py", line 136, in pred_param
    resids = np.array([model.predict(X[:, col_idx]) for model in models]).T
  File "C:\Users\sures\anaconda3\envs\venv\lib\site-packages\ngboost\ngboost.py", line 136, in <listcomp>
    resids = np.array([model.predict(X[:, col_idx]) for model in models]).T
IndexError: index 23 is out of bounds for axis 1 with size 23
[2025-08-02 19:37:11,343: INFO: model_predict: >>>>>> stage Model Prediction Stage started <<<<<<]
[2025-08-02 19:42:02,726: INFO: model_predict: Predictions saved at: artifacts/model_prediction/predictions.csv]
[2025-08-02 19:42:02,726: INFO: model_predict: Evaluation metrics saved at: artifacts/model_prediction/evaluation_metrics.csv]
[2025-08-02 19:42:02,726: INFO: model_predict: >>>>>> stage Model Prediction Stage completed <<<<<<

x==========x]
[2025-08-02 20:00:08,300: INFO: model_predict: >>>>>> stage Model Prediction Stage started <<<<<<]
[2025-08-02 20:00:09,828: ERROR: model_predict: name 'preprocessed_data' is not defined]
Traceback (most recent call last):
  File "C:\Users\sures\Downloads\Turbine_RUL_MLPipeline\model_predict.py", line 24, in <module>
    predictions_path, evaluation_metrics_path = obj.main()
  File "C:\Users\sures\Downloads\Turbine_RUL_MLPipeline\model_predict.py", line 16, in main
    predictions_path, evaluation_metrics_path = model_predictor.initiate_model_prediction()
  File "C:\Users\sures\Downloads\Turbine_RUL_MLPipeline\src\Turbine_RUL\components\model_prediction.py", line 193, in initiate_model_prediction
    test_long_h_fts = features_long_pipe.transform(preprocessed_data)
NameError: name 'preprocessed_data' is not defined
[2025-08-02 20:08:52,986: INFO: model_predict: >>>>>> stage Model Prediction Stage started <<<<<<]
[2025-08-02 20:13:44,731: ERROR: model_predict: index 22 is out of bounds for axis 1 with size 16]
Traceback (most recent call last):
  File "C:\Users\sures\Downloads\Turbine_RUL_MLPipeline\model_predict.py", line 29, in <module>
    predictions_path, evaluation_metrics_path = obj.main()
  File "C:\Users\sures\Downloads\Turbine_RUL_MLPipeline\model_predict.py", line 17, in main
    results = model_predictor.initiate_model_prediction()
  File "C:\Users\sures\Downloads\Turbine_RUL_MLPipeline\src\Turbine_RUL\components\model_prediction.py", line 425, in initiate_model_prediction
    predictions = self.make_predictions(X_test_prepared)
  File "C:\Users\sures\Downloads\Turbine_RUL_MLPipeline\src\Turbine_RUL\components\model_prediction.py", line 155, in make_predictions
    pred_rul = self.model.predict(X_test_prepared.values)
  File "C:\Users\sures\anaconda3\envs\venv\lib\site-packages\ngboost\ngboost.py", line 590, in predict
    return self.pred_dist(X, max_iter=max_iter).predict()
  File "C:\Users\sures\anaconda3\envs\venv\lib\site-packages\ngboost\ngboost.py", line 543, in pred_dist
    params = np.asarray(self.pred_param(X, max_iter))
  File "C:\Users\sures\anaconda3\envs\venv\lib\site-packages\ngboost\ngboost.py", line 136, in pred_param
    resids = np.array([model.predict(X[:, col_idx]) for model in models]).T
  File "C:\Users\sures\anaconda3\envs\venv\lib\site-packages\ngboost\ngboost.py", line 136, in <listcomp>
    resids = np.array([model.predict(X[:, col_idx]) for model in models]).T
IndexError: index 22 is out of bounds for axis 1 with size 16
[2025-08-02 20:14:54,794: INFO: model_predict: >>>>>> stage Model Prediction Stage started <<<<<<]
[2025-08-02 20:20:00,883: ERROR: model_predict: Feature mismatch! Model requires 26 features but only 26 are available. Missing features: {'14', '0', '6', '5', '19', '4', '3', '8', '2', '1'}. This indicates a pipeline inconsistency between training and prediction.]
Traceback (most recent call last):
  File "C:\Users\sures\Downloads\Turbine_RUL_MLPipeline\model_predict.py", line 29, in <module>
    predictions_path, evaluation_metrics_path = obj.main()
  File "C:\Users\sures\Downloads\Turbine_RUL_MLPipeline\model_predict.py", line 17, in main
    results = model_predictor.initiate_model_prediction()
  File "C:\Users\sures\Downloads\Turbine_RUL_MLPipeline\src\Turbine_RUL\components\model_prediction.py", line 443, in initiate_model_prediction
    X_test_prepared, engine_ids = self.prepare_prediction_data(test_features)
  File "C:\Users\sures\Downloads\Turbine_RUL_MLPipeline\src\Turbine_RUL\components\model_prediction.py", line 152, in prepare_prediction_data
    raise ValueError(
ValueError: Feature mismatch! Model requires 26 features but only 26 are available. Missing features: {'14', '0', '6', '5', '19', '4', '3', '8', '2', '1'}. This indicates a pipeline inconsistency between training and prediction.
[2025-08-02 20:46:11,862: INFO: model_predict: >>>>>> stage Model Prediction Stage started <<<<<<]
[2025-08-02 20:53:01,326: INFO: model_predict: Predictions saved at: artifacts/model_prediction/predictions.csv]
[2025-08-02 20:53:01,326: INFO: model_predict: Evaluation metrics saved at: artifacts/model_prediction/evaluation_metrics.csv]
[2025-08-02 20:53:01,326: INFO: model_predict: >>>>>> stage Model Prediction Stage completed <<<<<<

x==========x]
